Feature: About Sample # features/about.feature:6

  Scenario: Transaction Processing                           # features/about.feature:8
    Given Sample Database                                    # features/steps/about.py:6
    When Transactions are submitted                          # features/steps/about.py:11
    Then Enforce business policies with Logic (rules + code) # features/steps/about.py:16
      Traceback (most recent call last):
        File "/Users/tylerband/dev/ApiLogicServer/venv/lib/python3.11/site-packages/urllib3/connection.py", line 174, in _new_conn
          conn = connection.create_connection(
                 ^^^^^^^^^^^^^^^^^^^^^^^^^^^^^
        File "/Users/tylerband/dev/ApiLogicServer/venv/lib/python3.11/site-packages/urllib3/util/connection.py", line 95, in create_connection
          raise err
        File "/Users/tylerband/dev/ApiLogicServer/venv/lib/python3.11/site-packages/urllib3/util/connection.py", line 85, in create_connection
          sock.connect(sa)
      ConnectionRefusedError: [Errno 61] Connection refused
      
      During handling of the above exception, another exception occurred:
      
      Traceback (most recent call last):
        File "/Users/tylerband/dev/ApiLogicServer/venv/lib/python3.11/site-packages/urllib3/connectionpool.py", line 715, in urlopen
          httplib_response = self._make_request(
                             ^^^^^^^^^^^^^^^^^^^
        File "/Users/tylerband/dev/ApiLogicServer/venv/lib/python3.11/site-packages/urllib3/connectionpool.py", line 416, in _make_request
          conn.request(method, url, **httplib_request_kw)
        File "/Users/tylerband/dev/ApiLogicServer/venv/lib/python3.11/site-packages/urllib3/connection.py", line 244, in request
          super(HTTPConnection, self).request(method, url, body=body, headers=headers)
        File "/Library/Frameworks/Python.framework/Versions/3.11/lib/python3.11/http/client.py", line 1286, in request
          self._send_request(method, url, body, headers, encode_chunked)
        File "/Library/Frameworks/Python.framework/Versions/3.11/lib/python3.11/http/client.py", line 1332, in _send_request
          self.endheaders(body, encode_chunked=encode_chunked)
        File "/Library/Frameworks/Python.framework/Versions/3.11/lib/python3.11/http/client.py", line 1281, in endheaders
          self._send_output(message_body, encode_chunked=encode_chunked)
        File "/Library/Frameworks/Python.framework/Versions/3.11/lib/python3.11/http/client.py", line 1041, in _send_output
          self.send(msg)
        File "/Library/Frameworks/Python.framework/Versions/3.11/lib/python3.11/http/client.py", line 979, in send
          self.connect()
        File "/Users/tylerband/dev/ApiLogicServer/venv/lib/python3.11/site-packages/urllib3/connection.py", line 205, in connect
          conn = self._new_conn()
                 ^^^^^^^^^^^^^^^^
        File "/Users/tylerband/dev/ApiLogicServer/venv/lib/python3.11/site-packages/urllib3/connection.py", line 186, in _new_conn
          raise NewConnectionError(
      urllib3.exceptions.NewConnectionError: <urllib3.connection.HTTPConnection object at 0x105be0b50>: Failed to establish a new connection: [Errno 61] Connection refused
      
      During handling of the above exception, another exception occurred:
      
      Traceback (most recent call last):
        File "/Users/tylerband/dev/ApiLogicServer/venv/lib/python3.11/site-packages/requests/adapters.py", line 440, in send
          resp = conn.urlopen(
                 ^^^^^^^^^^^^^
        File "/Users/tylerband/dev/ApiLogicServer/venv/lib/python3.11/site-packages/urllib3/connectionpool.py", line 799, in urlopen
          retries = retries.increment(
                    ^^^^^^^^^^^^^^^^^^
        File "/Users/tylerband/dev/ApiLogicServer/venv/lib/python3.11/site-packages/urllib3/util/retry.py", line 592, in increment
          raise MaxRetryError(_pool, url, error or ResponseError(cause))
      urllib3.exceptions.MaxRetryError: HTTPConnectionPool(host='localhost', port=5656): Max retries exceeded with url: /server_log?msg=Rules%20Report&test=Transaction%20Processing&dir=test/api_logic_server_behave/logs/scenario_logic_logs (Caused by NewConnectionError('<urllib3.connection.HTTPConnection object at 0x105be0b50>: Failed to establish a new connection: [Errno 61] Connection refused'))
      
      During handling of the above exception, another exception occurred:
      
      Traceback (most recent call last):
        File "/Users/tylerband/dev/ApiLogicServer/venv/lib/python3.11/site-packages/behave/model.py", line 1329, in run
          match.run(runner.context)
        File "/Users/tylerband/dev/ApiLogicServer/venv/lib/python3.11/site-packages/behave/matchers.py", line 98, in run
          self.func(context, *args, **kwargs)
        File "features/steps/about.py", line 19, in step_impl
          test_utils.prt(f'Rules Report', scenario)
        File "/Users/tylerband/dev/ApiLogicServer/banking/test/api_logic_server_behave/features/steps/test_utils.py", line 24, in prt
          r = requests.get(msg_url)
              ^^^^^^^^^^^^^^^^^^^^^
        File "/Users/tylerband/dev/ApiLogicServer/venv/lib/python3.11/site-packages/requests/api.py", line 75, in get
          return request('get', url, params=params, **kwargs)
                 ^^^^^^^^^^^^^^^^^^^^^^^^^^^^^^^^^^^^^^^^^^^^
        File "/Users/tylerband/dev/ApiLogicServer/venv/lib/python3.11/site-packages/requests/api.py", line 61, in request
          return session.request(method=method, url=url, **kwargs)
                 ^^^^^^^^^^^^^^^^^^^^^^^^^^^^^^^^^^^^^^^^^^^^^^^^^
        File "/Users/tylerband/dev/ApiLogicServer/venv/lib/python3.11/site-packages/requests/sessions.py", line 529, in request
          resp = self.send(prep, **send_kwargs)
                 ^^^^^^^^^^^^^^^^^^^^^^^^^^^^^^
        File "/Users/tylerband/dev/ApiLogicServer/venv/lib/python3.11/site-packages/requests/sessions.py", line 645, in send
          r = adapter.send(request, **kwargs)
              ^^^^^^^^^^^^^^^^^^^^^^^^^^^^^^^
        File "/Users/tylerband/dev/ApiLogicServer/venv/lib/python3.11/site-packages/requests/adapters.py", line 519, in send
          raise ConnectionError(e, request=request)
      requests.exceptions.ConnectionError: HTTPConnectionPool(host='localhost', port=5656): Max retries exceeded with url: /server_log?msg=Rules%20Report&test=Transaction%20Processing&dir=test/api_logic_server_behave/logs/scenario_logic_logs (Caused by NewConnectionError('<urllib3.connection.HTTPConnection object at 0x105be0b50>: Failed to establish a new connection: [Errno 61] Connection refused'))


Feature: API GET Testing # features/api_get.feature:2

  Scenario: GET Customer Endpoint  # features/api_get.feature:4
    Given GET Customer endpoint    # features/steps/api_get.py:26
    When GET Customer API          # features/steps/api_get.py:30
      Traceback (most recent call last):
        File "/Users/tylerband/dev/ApiLogicServer/venv/lib/python3.11/site-packages/urllib3/connection.py", line 174, in _new_conn
          conn = connection.create_connection(
                 ^^^^^^^^^^^^^^^^^^^^^^^^^^^^^
        File "/Users/tylerband/dev/ApiLogicServer/venv/lib/python3.11/site-packages/urllib3/util/connection.py", line 95, in create_connection
          raise err
        File "/Users/tylerband/dev/ApiLogicServer/venv/lib/python3.11/site-packages/urllib3/util/connection.py", line 85, in create_connection
          sock.connect(sa)
      ConnectionRefusedError: [Errno 61] Connection refused
      
      During handling of the above exception, another exception occurred:
      
      Traceback (most recent call last):
        File "/Users/tylerband/dev/ApiLogicServer/venv/lib/python3.11/site-packages/urllib3/connectionpool.py", line 715, in urlopen
          httplib_response = self._make_request(
                             ^^^^^^^^^^^^^^^^^^^
        File "/Users/tylerband/dev/ApiLogicServer/venv/lib/python3.11/site-packages/urllib3/connectionpool.py", line 416, in _make_request
          conn.request(method, url, **httplib_request_kw)
        File "/Users/tylerband/dev/ApiLogicServer/venv/lib/python3.11/site-packages/urllib3/connection.py", line 244, in request
          super(HTTPConnection, self).request(method, url, body=body, headers=headers)
        File "/Library/Frameworks/Python.framework/Versions/3.11/lib/python3.11/http/client.py", line 1286, in request
          self._send_request(method, url, body, headers, encode_chunked)
        File "/Library/Frameworks/Python.framework/Versions/3.11/lib/python3.11/http/client.py", line 1332, in _send_request
          self.endheaders(body, encode_chunked=encode_chunked)
        File "/Library/Frameworks/Python.framework/Versions/3.11/lib/python3.11/http/client.py", line 1281, in endheaders
          self._send_output(message_body, encode_chunked=encode_chunked)
        File "/Library/Frameworks/Python.framework/Versions/3.11/lib/python3.11/http/client.py", line 1041, in _send_output
          self.send(msg)
        File "/Library/Frameworks/Python.framework/Versions/3.11/lib/python3.11/http/client.py", line 979, in send
          self.connect()
        File "/Users/tylerband/dev/ApiLogicServer/venv/lib/python3.11/site-packages/urllib3/connection.py", line 205, in connect
          conn = self._new_conn()
                 ^^^^^^^^^^^^^^^^
        File "/Users/tylerband/dev/ApiLogicServer/venv/lib/python3.11/site-packages/urllib3/connection.py", line 186, in _new_conn
          raise NewConnectionError(
      urllib3.exceptions.NewConnectionError: <urllib3.connection.HTTPConnection object at 0x105cbd590>: Failed to establish a new connection: [Errno 61] Connection refused
      
      During handling of the above exception, another exception occurred:
      
      Traceback (most recent call last):
        File "/Users/tylerband/dev/ApiLogicServer/venv/lib/python3.11/site-packages/requests/adapters.py", line 440, in send
          resp = conn.urlopen(
                 ^^^^^^^^^^^^^
        File "/Users/tylerband/dev/ApiLogicServer/venv/lib/python3.11/site-packages/urllib3/connectionpool.py", line 799, in urlopen
          retries = retries.increment(
                    ^^^^^^^^^^^^^^^^^^
        File "/Users/tylerband/dev/ApiLogicServer/venv/lib/python3.11/site-packages/urllib3/util/retry.py", line 592, in increment
          raise MaxRetryError(_pool, url, error or ResponseError(cause))
      urllib3.exceptions.MaxRetryError: HTTPConnectionPool(host='localhost', port=5656): Max retries exceeded with url: /api/auth/login (Caused by NewConnectionError('<urllib3.connection.HTTPConnection object at 0x105cbd590>: Failed to establish a new connection: [Errno 61] Connection refused'))
      
      During handling of the above exception, another exception occurred:
      
      Traceback (most recent call last):
        File "/Users/tylerband/dev/ApiLogicServer/venv/lib/python3.11/site-packages/behave/model.py", line 1329, in run
          match.run(runner.context)
        File "/Users/tylerband/dev/ApiLogicServer/venv/lib/python3.11/site-packages/behave/matchers.py", line 98, in run
          self.func(context, *args, **kwargs)
        File "features/steps/api_get.py", line 32, in step_impl
          context.response_text = getAPI('Customer')
                                  ^^^^^^^^^^^^^^^^^^
        File "features/steps/api_get.py", line 14, in getAPI
          r = requests.get(url=get_uri, headers= login())
                                                 ^^^^^^^
        File "/Users/tylerband/dev/ApiLogicServer/banking/test/api_logic_server_behave/features/steps/test_utils.py", line 51, in login
          r = requests.post(url=post_uri, json = post_data)
              ^^^^^^^^^^^^^^^^^^^^^^^^^^^^^^^^^^^^^^^^^^^^^
        File "/Users/tylerband/dev/ApiLogicServer/venv/lib/python3.11/site-packages/requests/api.py", line 117, in post
          return request('post', url, data=data, json=json, **kwargs)
                 ^^^^^^^^^^^^^^^^^^^^^^^^^^^^^^^^^^^^^^^^^^^^^^^^^^^^
        File "/Users/tylerband/dev/ApiLogicServer/venv/lib/python3.11/site-packages/requests/api.py", line 61, in request
          return session.request(method=method, url=url, **kwargs)
                 ^^^^^^^^^^^^^^^^^^^^^^^^^^^^^^^^^^^^^^^^^^^^^^^^^
        File "/Users/tylerband/dev/ApiLogicServer/venv/lib/python3.11/site-packages/requests/sessions.py", line 529, in request
          resp = self.send(prep, **send_kwargs)
                 ^^^^^^^^^^^^^^^^^^^^^^^^^^^^^^
        File "/Users/tylerband/dev/ApiLogicServer/venv/lib/python3.11/site-packages/requests/sessions.py", line 645, in send
          r = adapter.send(request, **kwargs)
              ^^^^^^^^^^^^^^^^^^^^^^^^^^^^^^^
        File "/Users/tylerband/dev/ApiLogicServer/venv/lib/python3.11/site-packages/requests/adapters.py", line 519, in send
          raise ConnectionError(e, request=request)
      requests.exceptions.ConnectionError: HTTPConnectionPool(host='localhost', port=5656): Max retries exceeded with url: /api/auth/login (Caused by NewConnectionError('<urllib3.connection.HTTPConnection object at 0x105cbd590>: Failed to establish a new connection: [Errno 61] Connection refused'))

    Then Customer retrieved        # None

  Scenario: GET Branch Endpoint  # features/api_get.feature:9
    Given GET Branch endpoint    # features/steps/api_get.py:39
    When GET Branch API          # features/steps/api_get.py:43
      Traceback (most recent call last):
        File "/Users/tylerband/dev/ApiLogicServer/venv/lib/python3.11/site-packages/urllib3/connection.py", line 174, in _new_conn
          conn = connection.create_connection(
                 ^^^^^^^^^^^^^^^^^^^^^^^^^^^^^
        File "/Users/tylerband/dev/ApiLogicServer/venv/lib/python3.11/site-packages/urllib3/util/connection.py", line 95, in create_connection
          raise err
        File "/Users/tylerband/dev/ApiLogicServer/venv/lib/python3.11/site-packages/urllib3/util/connection.py", line 85, in create_connection
          sock.connect(sa)
      ConnectionRefusedError: [Errno 61] Connection refused
      
      During handling of the above exception, another exception occurred:
      
      Traceback (most recent call last):
        File "/Users/tylerband/dev/ApiLogicServer/venv/lib/python3.11/site-packages/urllib3/connectionpool.py", line 715, in urlopen
          httplib_response = self._make_request(
                             ^^^^^^^^^^^^^^^^^^^
        File "/Users/tylerband/dev/ApiLogicServer/venv/lib/python3.11/site-packages/urllib3/connectionpool.py", line 416, in _make_request
          conn.request(method, url, **httplib_request_kw)
        File "/Users/tylerband/dev/ApiLogicServer/venv/lib/python3.11/site-packages/urllib3/connection.py", line 244, in request
          super(HTTPConnection, self).request(method, url, body=body, headers=headers)
        File "/Library/Frameworks/Python.framework/Versions/3.11/lib/python3.11/http/client.py", line 1286, in request
          self._send_request(method, url, body, headers, encode_chunked)
        File "/Library/Frameworks/Python.framework/Versions/3.11/lib/python3.11/http/client.py", line 1332, in _send_request
          self.endheaders(body, encode_chunked=encode_chunked)
        File "/Library/Frameworks/Python.framework/Versions/3.11/lib/python3.11/http/client.py", line 1281, in endheaders
          self._send_output(message_body, encode_chunked=encode_chunked)
        File "/Library/Frameworks/Python.framework/Versions/3.11/lib/python3.11/http/client.py", line 1041, in _send_output
          self.send(msg)
        File "/Library/Frameworks/Python.framework/Versions/3.11/lib/python3.11/http/client.py", line 979, in send
          self.connect()
        File "/Users/tylerband/dev/ApiLogicServer/venv/lib/python3.11/site-packages/urllib3/connection.py", line 205, in connect
          conn = self._new_conn()
                 ^^^^^^^^^^^^^^^^
        File "/Users/tylerband/dev/ApiLogicServer/venv/lib/python3.11/site-packages/urllib3/connection.py", line 186, in _new_conn
          raise NewConnectionError(
      urllib3.exceptions.NewConnectionError: <urllib3.connection.HTTPConnection object at 0x105cb5050>: Failed to establish a new connection: [Errno 61] Connection refused
      
      During handling of the above exception, another exception occurred:
      
      Traceback (most recent call last):
        File "/Users/tylerband/dev/ApiLogicServer/venv/lib/python3.11/site-packages/requests/adapters.py", line 440, in send
          resp = conn.urlopen(
                 ^^^^^^^^^^^^^
        File "/Users/tylerband/dev/ApiLogicServer/venv/lib/python3.11/site-packages/urllib3/connectionpool.py", line 799, in urlopen
          retries = retries.increment(
                    ^^^^^^^^^^^^^^^^^^
        File "/Users/tylerband/dev/ApiLogicServer/venv/lib/python3.11/site-packages/urllib3/util/retry.py", line 592, in increment
          raise MaxRetryError(_pool, url, error or ResponseError(cause))
      urllib3.exceptions.MaxRetryError: HTTPConnectionPool(host='localhost', port=5656): Max retries exceeded with url: /api/auth/login (Caused by NewConnectionError('<urllib3.connection.HTTPConnection object at 0x105cb5050>: Failed to establish a new connection: [Errno 61] Connection refused'))
      
      During handling of the above exception, another exception occurred:
      
      Traceback (most recent call last):
        File "/Users/tylerband/dev/ApiLogicServer/venv/lib/python3.11/site-packages/behave/model.py", line 1329, in run
          match.run(runner.context)
        File "/Users/tylerband/dev/ApiLogicServer/venv/lib/python3.11/site-packages/behave/matchers.py", line 98, in run
          self.func(context, *args, **kwargs)
        File "features/steps/api_get.py", line 45, in step_impl
          context.response_text = getAPI('Branch')
                                  ^^^^^^^^^^^^^^^^
        File "features/steps/api_get.py", line 14, in getAPI
          r = requests.get(url=get_uri, headers= login())
                                                 ^^^^^^^
        File "/Users/tylerband/dev/ApiLogicServer/banking/test/api_logic_server_behave/features/steps/test_utils.py", line 51, in login
          r = requests.post(url=post_uri, json = post_data)
              ^^^^^^^^^^^^^^^^^^^^^^^^^^^^^^^^^^^^^^^^^^^^^
        File "/Users/tylerband/dev/ApiLogicServer/venv/lib/python3.11/site-packages/requests/api.py", line 117, in post
          return request('post', url, data=data, json=json, **kwargs)
                 ^^^^^^^^^^^^^^^^^^^^^^^^^^^^^^^^^^^^^^^^^^^^^^^^^^^^
        File "/Users/tylerband/dev/ApiLogicServer/venv/lib/python3.11/site-packages/requests/api.py", line 61, in request
          return session.request(method=method, url=url, **kwargs)
                 ^^^^^^^^^^^^^^^^^^^^^^^^^^^^^^^^^^^^^^^^^^^^^^^^^
        File "/Users/tylerband/dev/ApiLogicServer/venv/lib/python3.11/site-packages/requests/sessions.py", line 529, in request
          resp = self.send(prep, **send_kwargs)
                 ^^^^^^^^^^^^^^^^^^^^^^^^^^^^^^
        File "/Users/tylerband/dev/ApiLogicServer/venv/lib/python3.11/site-packages/requests/sessions.py", line 645, in send
          r = adapter.send(request, **kwargs)
              ^^^^^^^^^^^^^^^^^^^^^^^^^^^^^^^
        File "/Users/tylerband/dev/ApiLogicServer/venv/lib/python3.11/site-packages/requests/adapters.py", line 519, in send
          raise ConnectionError(e, request=request)
      requests.exceptions.ConnectionError: HTTPConnectionPool(host='localhost', port=5656): Max retries exceeded with url: /api/auth/login (Caused by NewConnectionError('<urllib3.connection.HTTPConnection object at 0x105cb5050>: Failed to establish a new connection: [Errno 61] Connection refused'))

    Then Branch retrieved        # None

  Scenario: GET AccountType Endpoint  # features/api_get.feature:14
    Given GET AccountType endpoint    # features/steps/api_get.py:52
    When GET AccountType API          # features/steps/api_get.py:56
      Traceback (most recent call last):
        File "/Users/tylerband/dev/ApiLogicServer/venv/lib/python3.11/site-packages/urllib3/connection.py", line 174, in _new_conn
          conn = connection.create_connection(
                 ^^^^^^^^^^^^^^^^^^^^^^^^^^^^^
        File "/Users/tylerband/dev/ApiLogicServer/venv/lib/python3.11/site-packages/urllib3/util/connection.py", line 95, in create_connection
          raise err
        File "/Users/tylerband/dev/ApiLogicServer/venv/lib/python3.11/site-packages/urllib3/util/connection.py", line 85, in create_connection
          sock.connect(sa)
      ConnectionRefusedError: [Errno 61] Connection refused
      
      During handling of the above exception, another exception occurred:
      
      Traceback (most recent call last):
        File "/Users/tylerband/dev/ApiLogicServer/venv/lib/python3.11/site-packages/urllib3/connectionpool.py", line 715, in urlopen
          httplib_response = self._make_request(
                             ^^^^^^^^^^^^^^^^^^^
        File "/Users/tylerband/dev/ApiLogicServer/venv/lib/python3.11/site-packages/urllib3/connectionpool.py", line 416, in _make_request
          conn.request(method, url, **httplib_request_kw)
        File "/Users/tylerband/dev/ApiLogicServer/venv/lib/python3.11/site-packages/urllib3/connection.py", line 244, in request
          super(HTTPConnection, self).request(method, url, body=body, headers=headers)
        File "/Library/Frameworks/Python.framework/Versions/3.11/lib/python3.11/http/client.py", line 1286, in request
          self._send_request(method, url, body, headers, encode_chunked)
        File "/Library/Frameworks/Python.framework/Versions/3.11/lib/python3.11/http/client.py", line 1332, in _send_request
          self.endheaders(body, encode_chunked=encode_chunked)
        File "/Library/Frameworks/Python.framework/Versions/3.11/lib/python3.11/http/client.py", line 1281, in endheaders
          self._send_output(message_body, encode_chunked=encode_chunked)
        File "/Library/Frameworks/Python.framework/Versions/3.11/lib/python3.11/http/client.py", line 1041, in _send_output
          self.send(msg)
        File "/Library/Frameworks/Python.framework/Versions/3.11/lib/python3.11/http/client.py", line 979, in send
          self.connect()
        File "/Users/tylerband/dev/ApiLogicServer/venv/lib/python3.11/site-packages/urllib3/connection.py", line 205, in connect
          conn = self._new_conn()
                 ^^^^^^^^^^^^^^^^
        File "/Users/tylerband/dev/ApiLogicServer/venv/lib/python3.11/site-packages/urllib3/connection.py", line 186, in _new_conn
          raise NewConnectionError(
      urllib3.exceptions.NewConnectionError: <urllib3.connection.HTTPConnection object at 0x105cac4d0>: Failed to establish a new connection: [Errno 61] Connection refused
      
      During handling of the above exception, another exception occurred:
      
      Traceback (most recent call last):
        File "/Users/tylerband/dev/ApiLogicServer/venv/lib/python3.11/site-packages/requests/adapters.py", line 440, in send
          resp = conn.urlopen(
                 ^^^^^^^^^^^^^
        File "/Users/tylerband/dev/ApiLogicServer/venv/lib/python3.11/site-packages/urllib3/connectionpool.py", line 799, in urlopen
          retries = retries.increment(
                    ^^^^^^^^^^^^^^^^^^
        File "/Users/tylerband/dev/ApiLogicServer/venv/lib/python3.11/site-packages/urllib3/util/retry.py", line 592, in increment
          raise MaxRetryError(_pool, url, error or ResponseError(cause))
      urllib3.exceptions.MaxRetryError: HTTPConnectionPool(host='localhost', port=5656): Max retries exceeded with url: /api/auth/login (Caused by NewConnectionError('<urllib3.connection.HTTPConnection object at 0x105cac4d0>: Failed to establish a new connection: [Errno 61] Connection refused'))
      
      During handling of the above exception, another exception occurred:
      
      Traceback (most recent call last):
        File "/Users/tylerband/dev/ApiLogicServer/venv/lib/python3.11/site-packages/behave/model.py", line 1329, in run
          match.run(runner.context)
        File "/Users/tylerband/dev/ApiLogicServer/venv/lib/python3.11/site-packages/behave/matchers.py", line 98, in run
          self.func(context, *args, **kwargs)
        File "features/steps/api_get.py", line 58, in step_impl
          context.response_text = getAPI('AccountType')
                                  ^^^^^^^^^^^^^^^^^^^^^
        File "features/steps/api_get.py", line 14, in getAPI
          r = requests.get(url=get_uri, headers= login())
                                                 ^^^^^^^
        File "/Users/tylerband/dev/ApiLogicServer/banking/test/api_logic_server_behave/features/steps/test_utils.py", line 51, in login
          r = requests.post(url=post_uri, json = post_data)
              ^^^^^^^^^^^^^^^^^^^^^^^^^^^^^^^^^^^^^^^^^^^^^
        File "/Users/tylerband/dev/ApiLogicServer/venv/lib/python3.11/site-packages/requests/api.py", line 117, in post
          return request('post', url, data=data, json=json, **kwargs)
                 ^^^^^^^^^^^^^^^^^^^^^^^^^^^^^^^^^^^^^^^^^^^^^^^^^^^^
        File "/Users/tylerband/dev/ApiLogicServer/venv/lib/python3.11/site-packages/requests/api.py", line 61, in request
          return session.request(method=method, url=url, **kwargs)
                 ^^^^^^^^^^^^^^^^^^^^^^^^^^^^^^^^^^^^^^^^^^^^^^^^^
        File "/Users/tylerband/dev/ApiLogicServer/venv/lib/python3.11/site-packages/requests/sessions.py", line 529, in request
          resp = self.send(prep, **send_kwargs)
                 ^^^^^^^^^^^^^^^^^^^^^^^^^^^^^^
        File "/Users/tylerband/dev/ApiLogicServer/venv/lib/python3.11/site-packages/requests/sessions.py", line 645, in send
          r = adapter.send(request, **kwargs)
              ^^^^^^^^^^^^^^^^^^^^^^^^^^^^^^^
        File "/Users/tylerband/dev/ApiLogicServer/venv/lib/python3.11/site-packages/requests/adapters.py", line 519, in send
          raise ConnectionError(e, request=request)
      requests.exceptions.ConnectionError: HTTPConnectionPool(host='localhost', port=5656): Max retries exceeded with url: /api/auth/login (Caused by NewConnectionError('<urllib3.connection.HTTPConnection object at 0x105cac4d0>: Failed to establish a new connection: [Errno 61] Connection refused'))

    Then AccountType retrieved        # None

  Scenario: GET Account Endpoint  # features/api_get.feature:19
    Given GET Account endpoint    # features/steps/api_get.py:65
    When GET Account API          # features/steps/api_get.py:69
      Traceback (most recent call last):
        File "/Users/tylerband/dev/ApiLogicServer/venv/lib/python3.11/site-packages/urllib3/connection.py", line 174, in _new_conn
          conn = connection.create_connection(
                 ^^^^^^^^^^^^^^^^^^^^^^^^^^^^^
        File "/Users/tylerband/dev/ApiLogicServer/venv/lib/python3.11/site-packages/urllib3/util/connection.py", line 95, in create_connection
          raise err
        File "/Users/tylerband/dev/ApiLogicServer/venv/lib/python3.11/site-packages/urllib3/util/connection.py", line 85, in create_connection
          sock.connect(sa)
      ConnectionRefusedError: [Errno 61] Connection refused
      
      During handling of the above exception, another exception occurred:
      
      Traceback (most recent call last):
        File "/Users/tylerband/dev/ApiLogicServer/venv/lib/python3.11/site-packages/urllib3/connectionpool.py", line 715, in urlopen
          httplib_response = self._make_request(
                             ^^^^^^^^^^^^^^^^^^^
        File "/Users/tylerband/dev/ApiLogicServer/venv/lib/python3.11/site-packages/urllib3/connectionpool.py", line 416, in _make_request
          conn.request(method, url, **httplib_request_kw)
        File "/Users/tylerband/dev/ApiLogicServer/venv/lib/python3.11/site-packages/urllib3/connection.py", line 244, in request
          super(HTTPConnection, self).request(method, url, body=body, headers=headers)
        File "/Library/Frameworks/Python.framework/Versions/3.11/lib/python3.11/http/client.py", line 1286, in request
          self._send_request(method, url, body, headers, encode_chunked)
        File "/Library/Frameworks/Python.framework/Versions/3.11/lib/python3.11/http/client.py", line 1332, in _send_request
          self.endheaders(body, encode_chunked=encode_chunked)
        File "/Library/Frameworks/Python.framework/Versions/3.11/lib/python3.11/http/client.py", line 1281, in endheaders
          self._send_output(message_body, encode_chunked=encode_chunked)
        File "/Library/Frameworks/Python.framework/Versions/3.11/lib/python3.11/http/client.py", line 1041, in _send_output
          self.send(msg)
        File "/Library/Frameworks/Python.framework/Versions/3.11/lib/python3.11/http/client.py", line 979, in send
          self.connect()
        File "/Users/tylerband/dev/ApiLogicServer/venv/lib/python3.11/site-packages/urllib3/connection.py", line 205, in connect
          conn = self._new_conn()
                 ^^^^^^^^^^^^^^^^
        File "/Users/tylerband/dev/ApiLogicServer/venv/lib/python3.11/site-packages/urllib3/connection.py", line 186, in _new_conn
          raise NewConnectionError(
      urllib3.exceptions.NewConnectionError: <urllib3.connection.HTTPConnection object at 0x105caf590>: Failed to establish a new connection: [Errno 61] Connection refused
      
      During handling of the above exception, another exception occurred:
      
      Traceback (most recent call last):
        File "/Users/tylerband/dev/ApiLogicServer/venv/lib/python3.11/site-packages/requests/adapters.py", line 440, in send
          resp = conn.urlopen(
                 ^^^^^^^^^^^^^
        File "/Users/tylerband/dev/ApiLogicServer/venv/lib/python3.11/site-packages/urllib3/connectionpool.py", line 799, in urlopen
          retries = retries.increment(
                    ^^^^^^^^^^^^^^^^^^
        File "/Users/tylerband/dev/ApiLogicServer/venv/lib/python3.11/site-packages/urllib3/util/retry.py", line 592, in increment
          raise MaxRetryError(_pool, url, error or ResponseError(cause))
      urllib3.exceptions.MaxRetryError: HTTPConnectionPool(host='localhost', port=5656): Max retries exceeded with url: /api/auth/login (Caused by NewConnectionError('<urllib3.connection.HTTPConnection object at 0x105caf590>: Failed to establish a new connection: [Errno 61] Connection refused'))
      
      During handling of the above exception, another exception occurred:
      
      Traceback (most recent call last):
        File "/Users/tylerband/dev/ApiLogicServer/venv/lib/python3.11/site-packages/behave/model.py", line 1329, in run
          match.run(runner.context)
        File "/Users/tylerband/dev/ApiLogicServer/venv/lib/python3.11/site-packages/behave/matchers.py", line 98, in run
          self.func(context, *args, **kwargs)
        File "features/steps/api_get.py", line 71, in step_impl
          context.response_text = getAPI('Account')
                                  ^^^^^^^^^^^^^^^^^
        File "features/steps/api_get.py", line 14, in getAPI
          r = requests.get(url=get_uri, headers= login())
                                                 ^^^^^^^
        File "/Users/tylerband/dev/ApiLogicServer/banking/test/api_logic_server_behave/features/steps/test_utils.py", line 51, in login
          r = requests.post(url=post_uri, json = post_data)
              ^^^^^^^^^^^^^^^^^^^^^^^^^^^^^^^^^^^^^^^^^^^^^
        File "/Users/tylerband/dev/ApiLogicServer/venv/lib/python3.11/site-packages/requests/api.py", line 117, in post
          return request('post', url, data=data, json=json, **kwargs)
                 ^^^^^^^^^^^^^^^^^^^^^^^^^^^^^^^^^^^^^^^^^^^^^^^^^^^^
        File "/Users/tylerband/dev/ApiLogicServer/venv/lib/python3.11/site-packages/requests/api.py", line 61, in request
          return session.request(method=method, url=url, **kwargs)
                 ^^^^^^^^^^^^^^^^^^^^^^^^^^^^^^^^^^^^^^^^^^^^^^^^^
        File "/Users/tylerband/dev/ApiLogicServer/venv/lib/python3.11/site-packages/requests/sessions.py", line 529, in request
          resp = self.send(prep, **send_kwargs)
                 ^^^^^^^^^^^^^^^^^^^^^^^^^^^^^^
        File "/Users/tylerband/dev/ApiLogicServer/venv/lib/python3.11/site-packages/requests/sessions.py", line 645, in send
          r = adapter.send(request, **kwargs)
              ^^^^^^^^^^^^^^^^^^^^^^^^^^^^^^^
        File "/Users/tylerband/dev/ApiLogicServer/venv/lib/python3.11/site-packages/requests/adapters.py", line 519, in send
          raise ConnectionError(e, request=request)
      requests.exceptions.ConnectionError: HTTPConnectionPool(host='localhost', port=5656): Max retries exceeded with url: /api/auth/login (Caused by NewConnectionError('<urllib3.connection.HTTPConnection object at 0x105caf590>: Failed to establish a new connection: [Errno 61] Connection refused'))

    Then Account retrieved        # None

  Scenario: GET Transfer Endpoint  # features/api_get.feature:24
    Given GET Transfer endpoint    # features/steps/api_get.py:78
    When GET Transfer API          # features/steps/api_get.py:82
      Traceback (most recent call last):
        File "/Users/tylerband/dev/ApiLogicServer/venv/lib/python3.11/site-packages/urllib3/connection.py", line 174, in _new_conn
          conn = connection.create_connection(
                 ^^^^^^^^^^^^^^^^^^^^^^^^^^^^^
        File "/Users/tylerband/dev/ApiLogicServer/venv/lib/python3.11/site-packages/urllib3/util/connection.py", line 95, in create_connection
          raise err
        File "/Users/tylerband/dev/ApiLogicServer/venv/lib/python3.11/site-packages/urllib3/util/connection.py", line 85, in create_connection
          sock.connect(sa)
      ConnectionRefusedError: [Errno 61] Connection refused
      
      During handling of the above exception, another exception occurred:
      
      Traceback (most recent call last):
        File "/Users/tylerband/dev/ApiLogicServer/venv/lib/python3.11/site-packages/urllib3/connectionpool.py", line 715, in urlopen
          httplib_response = self._make_request(
                             ^^^^^^^^^^^^^^^^^^^
        File "/Users/tylerband/dev/ApiLogicServer/venv/lib/python3.11/site-packages/urllib3/connectionpool.py", line 416, in _make_request
          conn.request(method, url, **httplib_request_kw)
        File "/Users/tylerband/dev/ApiLogicServer/venv/lib/python3.11/site-packages/urllib3/connection.py", line 244, in request
          super(HTTPConnection, self).request(method, url, body=body, headers=headers)
        File "/Library/Frameworks/Python.framework/Versions/3.11/lib/python3.11/http/client.py", line 1286, in request
          self._send_request(method, url, body, headers, encode_chunked)
        File "/Library/Frameworks/Python.framework/Versions/3.11/lib/python3.11/http/client.py", line 1332, in _send_request
          self.endheaders(body, encode_chunked=encode_chunked)
        File "/Library/Frameworks/Python.framework/Versions/3.11/lib/python3.11/http/client.py", line 1281, in endheaders
          self._send_output(message_body, encode_chunked=encode_chunked)
        File "/Library/Frameworks/Python.framework/Versions/3.11/lib/python3.11/http/client.py", line 1041, in _send_output
          self.send(msg)
        File "/Library/Frameworks/Python.framework/Versions/3.11/lib/python3.11/http/client.py", line 979, in send
          self.connect()
        File "/Users/tylerband/dev/ApiLogicServer/venv/lib/python3.11/site-packages/urllib3/connection.py", line 205, in connect
          conn = self._new_conn()
                 ^^^^^^^^^^^^^^^^
        File "/Users/tylerband/dev/ApiLogicServer/venv/lib/python3.11/site-packages/urllib3/connection.py", line 186, in _new_conn
          raise NewConnectionError(
      urllib3.exceptions.NewConnectionError: <urllib3.connection.HTTPConnection object at 0x105cce890>: Failed to establish a new connection: [Errno 61] Connection refused
      
      During handling of the above exception, another exception occurred:
      
      Traceback (most recent call last):
        File "/Users/tylerband/dev/ApiLogicServer/venv/lib/python3.11/site-packages/requests/adapters.py", line 440, in send
          resp = conn.urlopen(
                 ^^^^^^^^^^^^^
        File "/Users/tylerband/dev/ApiLogicServer/venv/lib/python3.11/site-packages/urllib3/connectionpool.py", line 799, in urlopen
          retries = retries.increment(
                    ^^^^^^^^^^^^^^^^^^
        File "/Users/tylerband/dev/ApiLogicServer/venv/lib/python3.11/site-packages/urllib3/util/retry.py", line 592, in increment
          raise MaxRetryError(_pool, url, error or ResponseError(cause))
      urllib3.exceptions.MaxRetryError: HTTPConnectionPool(host='localhost', port=5656): Max retries exceeded with url: /api/auth/login (Caused by NewConnectionError('<urllib3.connection.HTTPConnection object at 0x105cce890>: Failed to establish a new connection: [Errno 61] Connection refused'))
      
      During handling of the above exception, another exception occurred:
      
      Traceback (most recent call last):
        File "/Users/tylerband/dev/ApiLogicServer/venv/lib/python3.11/site-packages/behave/model.py", line 1329, in run
          match.run(runner.context)
        File "/Users/tylerband/dev/ApiLogicServer/venv/lib/python3.11/site-packages/behave/matchers.py", line 98, in run
          self.func(context, *args, **kwargs)
        File "features/steps/api_get.py", line 84, in step_impl
          context.response_text = getAPI('Transfer')
                                  ^^^^^^^^^^^^^^^^^^
        File "features/steps/api_get.py", line 14, in getAPI
          r = requests.get(url=get_uri, headers= login())
                                                 ^^^^^^^
        File "/Users/tylerband/dev/ApiLogicServer/banking/test/api_logic_server_behave/features/steps/test_utils.py", line 51, in login
          r = requests.post(url=post_uri, json = post_data)
              ^^^^^^^^^^^^^^^^^^^^^^^^^^^^^^^^^^^^^^^^^^^^^
        File "/Users/tylerband/dev/ApiLogicServer/venv/lib/python3.11/site-packages/requests/api.py", line 117, in post
          return request('post', url, data=data, json=json, **kwargs)
                 ^^^^^^^^^^^^^^^^^^^^^^^^^^^^^^^^^^^^^^^^^^^^^^^^^^^^
        File "/Users/tylerband/dev/ApiLogicServer/venv/lib/python3.11/site-packages/requests/api.py", line 61, in request
          return session.request(method=method, url=url, **kwargs)
                 ^^^^^^^^^^^^^^^^^^^^^^^^^^^^^^^^^^^^^^^^^^^^^^^^^
        File "/Users/tylerband/dev/ApiLogicServer/venv/lib/python3.11/site-packages/requests/sessions.py", line 529, in request
          resp = self.send(prep, **send_kwargs)
                 ^^^^^^^^^^^^^^^^^^^^^^^^^^^^^^
        File "/Users/tylerband/dev/ApiLogicServer/venv/lib/python3.11/site-packages/requests/sessions.py", line 645, in send
          r = adapter.send(request, **kwargs)
              ^^^^^^^^^^^^^^^^^^^^^^^^^^^^^^^
        File "/Users/tylerband/dev/ApiLogicServer/venv/lib/python3.11/site-packages/requests/adapters.py", line 519, in send
          raise ConnectionError(e, request=request)
      requests.exceptions.ConnectionError: HTTPConnectionPool(host='localhost', port=5656): Max retries exceeded with url: /api/auth/login (Caused by NewConnectionError('<urllib3.connection.HTTPConnection object at 0x105cce890>: Failed to establish a new connection: [Errno 61] Connection refused'))

    Then Transfer retrieved        # None

  Scenario: GET Employee Endpoint  # features/api_get.feature:29
    Given GET Employee endpoint    # features/steps/api_get.py:91
    When GET Employee API          # features/steps/api_get.py:95
      Traceback (most recent call last):
        File "/Users/tylerband/dev/ApiLogicServer/venv/lib/python3.11/site-packages/urllib3/connection.py", line 174, in _new_conn
          conn = connection.create_connection(
                 ^^^^^^^^^^^^^^^^^^^^^^^^^^^^^
        File "/Users/tylerband/dev/ApiLogicServer/venv/lib/python3.11/site-packages/urllib3/util/connection.py", line 95, in create_connection
          raise err
        File "/Users/tylerband/dev/ApiLogicServer/venv/lib/python3.11/site-packages/urllib3/util/connection.py", line 85, in create_connection
          sock.connect(sa)
      ConnectionRefusedError: [Errno 61] Connection refused
      
      During handling of the above exception, another exception occurred:
      
      Traceback (most recent call last):
        File "/Users/tylerband/dev/ApiLogicServer/venv/lib/python3.11/site-packages/urllib3/connectionpool.py", line 715, in urlopen
          httplib_response = self._make_request(
                             ^^^^^^^^^^^^^^^^^^^
        File "/Users/tylerband/dev/ApiLogicServer/venv/lib/python3.11/site-packages/urllib3/connectionpool.py", line 416, in _make_request
          conn.request(method, url, **httplib_request_kw)
        File "/Users/tylerband/dev/ApiLogicServer/venv/lib/python3.11/site-packages/urllib3/connection.py", line 244, in request
          super(HTTPConnection, self).request(method, url, body=body, headers=headers)
        File "/Library/Frameworks/Python.framework/Versions/3.11/lib/python3.11/http/client.py", line 1286, in request
          self._send_request(method, url, body, headers, encode_chunked)
        File "/Library/Frameworks/Python.framework/Versions/3.11/lib/python3.11/http/client.py", line 1332, in _send_request
          self.endheaders(body, encode_chunked=encode_chunked)
        File "/Library/Frameworks/Python.framework/Versions/3.11/lib/python3.11/http/client.py", line 1281, in endheaders
          self._send_output(message_body, encode_chunked=encode_chunked)
        File "/Library/Frameworks/Python.framework/Versions/3.11/lib/python3.11/http/client.py", line 1041, in _send_output
          self.send(msg)
        File "/Library/Frameworks/Python.framework/Versions/3.11/lib/python3.11/http/client.py", line 979, in send
          self.connect()
        File "/Users/tylerband/dev/ApiLogicServer/venv/lib/python3.11/site-packages/urllib3/connection.py", line 205, in connect
          conn = self._new_conn()
                 ^^^^^^^^^^^^^^^^
        File "/Users/tylerband/dev/ApiLogicServer/venv/lib/python3.11/site-packages/urllib3/connection.py", line 186, in _new_conn
          raise NewConnectionError(
      urllib3.exceptions.NewConnectionError: <urllib3.connection.HTTPConnection object at 0x105cd9ad0>: Failed to establish a new connection: [Errno 61] Connection refused
      
      During handling of the above exception, another exception occurred:
      
      Traceback (most recent call last):
        File "/Users/tylerband/dev/ApiLogicServer/venv/lib/python3.11/site-packages/requests/adapters.py", line 440, in send
          resp = conn.urlopen(
                 ^^^^^^^^^^^^^
        File "/Users/tylerband/dev/ApiLogicServer/venv/lib/python3.11/site-packages/urllib3/connectionpool.py", line 799, in urlopen
          retries = retries.increment(
                    ^^^^^^^^^^^^^^^^^^
        File "/Users/tylerband/dev/ApiLogicServer/venv/lib/python3.11/site-packages/urllib3/util/retry.py", line 592, in increment
          raise MaxRetryError(_pool, url, error or ResponseError(cause))
      urllib3.exceptions.MaxRetryError: HTTPConnectionPool(host='localhost', port=5656): Max retries exceeded with url: /api/auth/login (Caused by NewConnectionError('<urllib3.connection.HTTPConnection object at 0x105cd9ad0>: Failed to establish a new connection: [Errno 61] Connection refused'))
      
      During handling of the above exception, another exception occurred:
      
      Traceback (most recent call last):
        File "/Users/tylerband/dev/ApiLogicServer/venv/lib/python3.11/site-packages/behave/model.py", line 1329, in run
          match.run(runner.context)
        File "/Users/tylerband/dev/ApiLogicServer/venv/lib/python3.11/site-packages/behave/matchers.py", line 98, in run
          self.func(context, *args, **kwargs)
        File "features/steps/api_get.py", line 97, in step_impl
          context.response_text = getAPI('Employee')
                                  ^^^^^^^^^^^^^^^^^^
        File "features/steps/api_get.py", line 14, in getAPI
          r = requests.get(url=get_uri, headers= login())
                                                 ^^^^^^^
        File "/Users/tylerband/dev/ApiLogicServer/banking/test/api_logic_server_behave/features/steps/test_utils.py", line 51, in login
          r = requests.post(url=post_uri, json = post_data)
              ^^^^^^^^^^^^^^^^^^^^^^^^^^^^^^^^^^^^^^^^^^^^^
        File "/Users/tylerband/dev/ApiLogicServer/venv/lib/python3.11/site-packages/requests/api.py", line 117, in post
          return request('post', url, data=data, json=json, **kwargs)
                 ^^^^^^^^^^^^^^^^^^^^^^^^^^^^^^^^^^^^^^^^^^^^^^^^^^^^
        File "/Users/tylerband/dev/ApiLogicServer/venv/lib/python3.11/site-packages/requests/api.py", line 61, in request
          return session.request(method=method, url=url, **kwargs)
                 ^^^^^^^^^^^^^^^^^^^^^^^^^^^^^^^^^^^^^^^^^^^^^^^^^
        File "/Users/tylerband/dev/ApiLogicServer/venv/lib/python3.11/site-packages/requests/sessions.py", line 529, in request
          resp = self.send(prep, **send_kwargs)
                 ^^^^^^^^^^^^^^^^^^^^^^^^^^^^^^
        File "/Users/tylerband/dev/ApiLogicServer/venv/lib/python3.11/site-packages/requests/sessions.py", line 645, in send
          r = adapter.send(request, **kwargs)
              ^^^^^^^^^^^^^^^^^^^^^^^^^^^^^^^
        File "/Users/tylerband/dev/ApiLogicServer/venv/lib/python3.11/site-packages/requests/adapters.py", line 519, in send
          raise ConnectionError(e, request=request)
      requests.exceptions.ConnectionError: HTTPConnectionPool(host='localhost', port=5656): Max retries exceeded with url: /api/auth/login (Caused by NewConnectionError('<urllib3.connection.HTTPConnection object at 0x105cd9ad0>: Failed to establish a new connection: [Errno 61] Connection refused'))

    Then Employee retrieved        # None

  Scenario: GET Transaction Endpoint  # features/api_get.feature:34
    Given GET Transaction endpoint    # features/steps/api_get.py:104
    When GET Transaction API          # features/steps/api_get.py:108
      Traceback (most recent call last):
        File "/Users/tylerband/dev/ApiLogicServer/venv/lib/python3.11/site-packages/urllib3/connection.py", line 174, in _new_conn
          conn = connection.create_connection(
                 ^^^^^^^^^^^^^^^^^^^^^^^^^^^^^
        File "/Users/tylerband/dev/ApiLogicServer/venv/lib/python3.11/site-packages/urllib3/util/connection.py", line 95, in create_connection
          raise err
        File "/Users/tylerband/dev/ApiLogicServer/venv/lib/python3.11/site-packages/urllib3/util/connection.py", line 85, in create_connection
          sock.connect(sa)
      ConnectionRefusedError: [Errno 61] Connection refused
      
      During handling of the above exception, another exception occurred:
      
      Traceback (most recent call last):
        File "/Users/tylerband/dev/ApiLogicServer/venv/lib/python3.11/site-packages/urllib3/connectionpool.py", line 715, in urlopen
          httplib_response = self._make_request(
                             ^^^^^^^^^^^^^^^^^^^
        File "/Users/tylerband/dev/ApiLogicServer/venv/lib/python3.11/site-packages/urllib3/connectionpool.py", line 416, in _make_request
          conn.request(method, url, **httplib_request_kw)
        File "/Users/tylerband/dev/ApiLogicServer/venv/lib/python3.11/site-packages/urllib3/connection.py", line 244, in request
          super(HTTPConnection, self).request(method, url, body=body, headers=headers)
        File "/Library/Frameworks/Python.framework/Versions/3.11/lib/python3.11/http/client.py", line 1286, in request
          self._send_request(method, url, body, headers, encode_chunked)
        File "/Library/Frameworks/Python.framework/Versions/3.11/lib/python3.11/http/client.py", line 1332, in _send_request
          self.endheaders(body, encode_chunked=encode_chunked)
        File "/Library/Frameworks/Python.framework/Versions/3.11/lib/python3.11/http/client.py", line 1281, in endheaders
          self._send_output(message_body, encode_chunked=encode_chunked)
        File "/Library/Frameworks/Python.framework/Versions/3.11/lib/python3.11/http/client.py", line 1041, in _send_output
          self.send(msg)
        File "/Library/Frameworks/Python.framework/Versions/3.11/lib/python3.11/http/client.py", line 979, in send
          self.connect()
        File "/Users/tylerband/dev/ApiLogicServer/venv/lib/python3.11/site-packages/urllib3/connection.py", line 205, in connect
          conn = self._new_conn()
                 ^^^^^^^^^^^^^^^^
        File "/Users/tylerband/dev/ApiLogicServer/venv/lib/python3.11/site-packages/urllib3/connection.py", line 186, in _new_conn
          raise NewConnectionError(
      urllib3.exceptions.NewConnectionError: <urllib3.connection.HTTPConnection object at 0x105cdcd90>: Failed to establish a new connection: [Errno 61] Connection refused
      
      During handling of the above exception, another exception occurred:
      
      Traceback (most recent call last):
        File "/Users/tylerband/dev/ApiLogicServer/venv/lib/python3.11/site-packages/requests/adapters.py", line 440, in send
          resp = conn.urlopen(
                 ^^^^^^^^^^^^^
        File "/Users/tylerband/dev/ApiLogicServer/venv/lib/python3.11/site-packages/urllib3/connectionpool.py", line 799, in urlopen
          retries = retries.increment(
                    ^^^^^^^^^^^^^^^^^^
        File "/Users/tylerband/dev/ApiLogicServer/venv/lib/python3.11/site-packages/urllib3/util/retry.py", line 592, in increment
          raise MaxRetryError(_pool, url, error or ResponseError(cause))
      urllib3.exceptions.MaxRetryError: HTTPConnectionPool(host='localhost', port=5656): Max retries exceeded with url: /api/auth/login (Caused by NewConnectionError('<urllib3.connection.HTTPConnection object at 0x105cdcd90>: Failed to establish a new connection: [Errno 61] Connection refused'))
      
      During handling of the above exception, another exception occurred:
      
      Traceback (most recent call last):
        File "/Users/tylerband/dev/ApiLogicServer/venv/lib/python3.11/site-packages/behave/model.py", line 1329, in run
          match.run(runner.context)
        File "/Users/tylerband/dev/ApiLogicServer/venv/lib/python3.11/site-packages/behave/matchers.py", line 98, in run
          self.func(context, *args, **kwargs)
        File "features/steps/api_get.py", line 110, in step_impl
          context.response_text = getAPI('Transaction')
                                  ^^^^^^^^^^^^^^^^^^^^^
        File "features/steps/api_get.py", line 14, in getAPI
          r = requests.get(url=get_uri, headers= login())
                                                 ^^^^^^^
        File "/Users/tylerband/dev/ApiLogicServer/banking/test/api_logic_server_behave/features/steps/test_utils.py", line 51, in login
          r = requests.post(url=post_uri, json = post_data)
              ^^^^^^^^^^^^^^^^^^^^^^^^^^^^^^^^^^^^^^^^^^^^^
        File "/Users/tylerband/dev/ApiLogicServer/venv/lib/python3.11/site-packages/requests/api.py", line 117, in post
          return request('post', url, data=data, json=json, **kwargs)
                 ^^^^^^^^^^^^^^^^^^^^^^^^^^^^^^^^^^^^^^^^^^^^^^^^^^^^
        File "/Users/tylerband/dev/ApiLogicServer/venv/lib/python3.11/site-packages/requests/api.py", line 61, in request
          return session.request(method=method, url=url, **kwargs)
                 ^^^^^^^^^^^^^^^^^^^^^^^^^^^^^^^^^^^^^^^^^^^^^^^^^
        File "/Users/tylerband/dev/ApiLogicServer/venv/lib/python3.11/site-packages/requests/sessions.py", line 529, in request
          resp = self.send(prep, **send_kwargs)
                 ^^^^^^^^^^^^^^^^^^^^^^^^^^^^^^
        File "/Users/tylerband/dev/ApiLogicServer/venv/lib/python3.11/site-packages/requests/sessions.py", line 645, in send
          r = adapter.send(request, **kwargs)
              ^^^^^^^^^^^^^^^^^^^^^^^^^^^^^^^
        File "/Users/tylerband/dev/ApiLogicServer/venv/lib/python3.11/site-packages/requests/adapters.py", line 519, in send
          raise ConnectionError(e, request=request)
      requests.exceptions.ConnectionError: HTTPConnectionPool(host='localhost', port=5656): Max retries exceeded with url: /api/auth/login (Caused by NewConnectionError('<urllib3.connection.HTTPConnection object at 0x105cdcd90>: Failed to establish a new connection: [Errno 61] Connection refused'))

    Then Transaction retrieved        # None

Feature: Transfer Funds # features/transfer_funds.feature:1

  Scenario: Transfer From Savings to Checking  # features/transfer_funds.feature:3
    Given Transfer Transaction                 # features/steps/transfer_funds.py:21
    When Transfer submitted                    # features/steps/transfer_funds.py:25
      Traceback (most recent call last):
        File "/Users/tylerband/dev/ApiLogicServer/venv/lib/python3.11/site-packages/urllib3/connection.py", line 174, in _new_conn
          conn = connection.create_connection(
                 ^^^^^^^^^^^^^^^^^^^^^^^^^^^^^
        File "/Users/tylerband/dev/ApiLogicServer/venv/lib/python3.11/site-packages/urllib3/util/connection.py", line 95, in create_connection
          raise err
        File "/Users/tylerband/dev/ApiLogicServer/venv/lib/python3.11/site-packages/urllib3/util/connection.py", line 85, in create_connection
          sock.connect(sa)
      ConnectionRefusedError: [Errno 61] Connection refused
      
      During handling of the above exception, another exception occurred:
      
      Traceback (most recent call last):
        File "/Users/tylerband/dev/ApiLogicServer/venv/lib/python3.11/site-packages/urllib3/connectionpool.py", line 715, in urlopen
          httplib_response = self._make_request(
                             ^^^^^^^^^^^^^^^^^^^
        File "/Users/tylerband/dev/ApiLogicServer/venv/lib/python3.11/site-packages/urllib3/connectionpool.py", line 416, in _make_request
          conn.request(method, url, **httplib_request_kw)
        File "/Users/tylerband/dev/ApiLogicServer/venv/lib/python3.11/site-packages/urllib3/connection.py", line 244, in request
          super(HTTPConnection, self).request(method, url, body=body, headers=headers)
        File "/Library/Frameworks/Python.framework/Versions/3.11/lib/python3.11/http/client.py", line 1286, in request
          self._send_request(method, url, body, headers, encode_chunked)
        File "/Library/Frameworks/Python.framework/Versions/3.11/lib/python3.11/http/client.py", line 1332, in _send_request
          self.endheaders(body, encode_chunked=encode_chunked)
        File "/Library/Frameworks/Python.framework/Versions/3.11/lib/python3.11/http/client.py", line 1281, in endheaders
          self._send_output(message_body, encode_chunked=encode_chunked)
        File "/Library/Frameworks/Python.framework/Versions/3.11/lib/python3.11/http/client.py", line 1041, in _send_output
          self.send(msg)
        File "/Library/Frameworks/Python.framework/Versions/3.11/lib/python3.11/http/client.py", line 979, in send
          self.connect()
        File "/Users/tylerband/dev/ApiLogicServer/venv/lib/python3.11/site-packages/urllib3/connection.py", line 205, in connect
          conn = self._new_conn()
                 ^^^^^^^^^^^^^^^^
        File "/Users/tylerband/dev/ApiLogicServer/venv/lib/python3.11/site-packages/urllib3/connection.py", line 186, in _new_conn
          raise NewConnectionError(
      urllib3.exceptions.NewConnectionError: <urllib3.connection.HTTPConnection object at 0x105cdff50>: Failed to establish a new connection: [Errno 61] Connection refused
      
      During handling of the above exception, another exception occurred:
      
      Traceback (most recent call last):
        File "/Users/tylerband/dev/ApiLogicServer/venv/lib/python3.11/site-packages/requests/adapters.py", line 440, in send
          resp = conn.urlopen(
                 ^^^^^^^^^^^^^
        File "/Users/tylerband/dev/ApiLogicServer/venv/lib/python3.11/site-packages/urllib3/connectionpool.py", line 799, in urlopen
          retries = retries.increment(
                    ^^^^^^^^^^^^^^^^^^
        File "/Users/tylerband/dev/ApiLogicServer/venv/lib/python3.11/site-packages/urllib3/util/retry.py", line 592, in increment
          raise MaxRetryError(_pool, url, error or ResponseError(cause))
      urllib3.exceptions.MaxRetryError: HTTPConnectionPool(host='localhost', port=5656): Max retries exceeded with url: /api/auth/login (Caused by NewConnectionError('<urllib3.connection.HTTPConnection object at 0x105cdff50>: Failed to establish a new connection: [Errno 61] Connection refused'))
      
      During handling of the above exception, another exception occurred:
      
      Traceback (most recent call last):
        File "/Users/tylerband/dev/ApiLogicServer/venv/lib/python3.11/site-packages/behave/model.py", line 1329, in run
          match.run(runner.context)
        File "/Users/tylerband/dev/ApiLogicServer/venv/lib/python3.11/site-packages/behave/matchers.py", line 98, in run
          self.func(context, *args, **kwargs)
        File "features/steps/transfer_funds.py", line 41, in step_impl
          r = requests.post(url=transfer_uri, json=transfer_args, headers=login())
                                                                          ^^^^^^^
        File "/Users/tylerband/dev/ApiLogicServer/banking/test/api_logic_server_behave/features/steps/test_utils.py", line 51, in login
          r = requests.post(url=post_uri, json = post_data)
              ^^^^^^^^^^^^^^^^^^^^^^^^^^^^^^^^^^^^^^^^^^^^^
        File "/Users/tylerband/dev/ApiLogicServer/venv/lib/python3.11/site-packages/requests/api.py", line 117, in post
          return request('post', url, data=data, json=json, **kwargs)
                 ^^^^^^^^^^^^^^^^^^^^^^^^^^^^^^^^^^^^^^^^^^^^^^^^^^^^
        File "/Users/tylerband/dev/ApiLogicServer/venv/lib/python3.11/site-packages/requests/api.py", line 61, in request
          return session.request(method=method, url=url, **kwargs)
                 ^^^^^^^^^^^^^^^^^^^^^^^^^^^^^^^^^^^^^^^^^^^^^^^^^
        File "/Users/tylerband/dev/ApiLogicServer/venv/lib/python3.11/site-packages/requests/sessions.py", line 529, in request
          resp = self.send(prep, **send_kwargs)
                 ^^^^^^^^^^^^^^^^^^^^^^^^^^^^^^
        File "/Users/tylerband/dev/ApiLogicServer/venv/lib/python3.11/site-packages/requests/sessions.py", line 645, in send
          r = adapter.send(request, **kwargs)
              ^^^^^^^^^^^^^^^^^^^^^^^^^^^^^^^
        File "/Users/tylerband/dev/ApiLogicServer/venv/lib/python3.11/site-packages/requests/adapters.py", line 519, in send
          raise ConnectionError(e, request=request)
      requests.exceptions.ConnectionError: HTTPConnectionPool(host='localhost', port=5656): Max retries exceeded with url: /api/auth/login (Caused by NewConnectionError('<urllib3.connection.HTTPConnection object at 0x105cdff50>: Failed to establish a new connection: [Errno 61] Connection refused'))
      
      Captured stdout:
      
      
      
      Transfer From Savings to Checking - verify transfer...
       Transfer From Savings to Checking

    Then Rules Fire and Transaction Success    # None

&nbsp;&nbsp;
/Users/tylerband/dev/ApiLogicServer/banking/test/api_logic_server_behave/behave_run.py completed at February 29, 2024 10:28:17